reported_result/report-0/ART_AutoISP_MC/output/output8.txt

Limit	1	3	6	5	2	SELL	2	---	0
NewOrderRs	Eliminated
	Trades	0
	Orders	0
	Credits	7
	Credit	1	12
	Credit	2	6
	Credit	3	9
	Credit	4	13
	Credit	5	4
	Credit	6	13
	Credit	7	14
	Ownerships	7
	Ownership	1	80
	Ownership	2	35
	Ownership	3	41
	Ownership	4	16
	Ownership	5	18
	Ownership	6	27
	Ownership	7	42
	ReferencePrice	5
	StaticPriceBandLowerLimit	0.6
	StaticPriceBandUpperLimit	0.8
	TotalShares	100
	OwnershipUpperLimit	0.2
	TickSize	1
	LotSize	1
Limit	2	3	2	5	6	SELL	0	---	0
NewOrderRs	Accepted
	Trades	0
	Orders	1
	Order	Limit	2	3	2	5	6	SELL	0	---	0
	Credits	7
	Credit	1	12
	Credit	2	6
	Credit	3	9
	Credit	4	13
	Credit	5	4
	Credit	6	13
	Credit	7	14
	Ownerships	7
	Ownership	1	80
	Ownership	2	35
	Ownership	3	41
	Ownership	4	16
	Ownership	5	18
	Ownership	6	27
	Ownership	7	42
	ReferencePrice	5
	StaticPriceBandLowerLimit	0.6
	StaticPriceBandUpperLimit	0.8
	TotalShares	100
	OwnershipUpperLimit	0.2
	TickSize	1
	LotSize	1
Iceberg	3	5	5	4	5	BUY 	3	---	0
NewOrderRs	Rejected
	Trades	0
	Orders	1
	Order	Limit	2	3	2	5	6	SELL	0	---	0
	Credits	7
	Credit	1	12
	Credit	2	6
	Credit	3	9
	Credit	4	13
	Credit	5	4
	Credit	6	13
	Credit	7	14
	Ownerships	7
	Ownership	1	80
	Ownership	2	35
	Ownership	3	41
	Ownership	4	16
	Ownership	5	18
	Ownership	6	27
	Ownership	7	42
	ReferencePrice	5
	StaticPriceBandLowerLimit	0.6
	StaticPriceBandUpperLimit	0.8
	TotalShares	100
	OwnershipUpperLimit	0.2
	TickSize	1
	LotSize	1
Iceberg	4	7	3	9	7	BUY 	2	---	0
NewOrderRs	Rejected
	Trades	0
	Orders	1
	Order	Limit	2	3	2	5	6	SELL	0	---	0
	Credits	7
	Credit	1	12
	Credit	2	6
	Credit	3	9
	Credit	4	13
	Credit	5	4
	Credit	6	13
	Credit	7	14
	Ownerships	7
	Ownership	1	80
	Ownership	2	35
	Ownership	3	41
	Ownership	4	16
	Ownership	5	18
	Ownership	6	27
	Ownership	7	42
	ReferencePrice	5
	StaticPriceBandLowerLimit	0.6
	StaticPriceBandUpperLimit	0.8
	TotalShares	100
	OwnershipUpperLimit	0.2
	TickSize	1
	LotSize	1
CancelOrderRs	Rejected
	Orders	1
	Order	Limit	2	3	2	5	6	SELL	0	---	0
	Credits	7
	Credit	1	12
	Credit	2	6
	Credit	3	9
	Credit	4	13
	Credit	5	4
	Credit	6	13
	Credit	7	14
	Ownerships	7
	Ownership	1	80
	Ownership	2	35
	Ownership	3	41
	Ownership	4	16
	Ownership	5	18
	Ownership	6	27
	Ownership	7	42
	ReferencePrice	5
	StaticPriceBandLowerLimit	0.6
	StaticPriceBandUpperLimit	0.8
	TotalShares	100
	OwnershipUpperLimit	0.2
	TickSize	1
	LotSize	1
Limit	6	7	2	3	8	SELL	0	---	0
NewOrderRs	Accepted
	Trades	0
	Orders	2
	Order	Limit	6	7	2	3	8	SELL	0	---	0
	Order	Limit	2	3	2	5	6	SELL	0	---	0
	Credits	7
	Credit	1	12
	Credit	2	6
	Credit	3	9
	Credit	4	13
	Credit	5	4
	Credit	6	13
	Credit	7	14
	Ownerships	7
	Ownership	1	80
	Ownership	2	35
	Ownership	3	41
	Ownership	4	16
	Ownership	5	18
	Ownership	6	27
	Ownership	7	42
	ReferencePrice	5
	StaticPriceBandLowerLimit	0.6
	StaticPriceBandUpperLimit	0.8
	TotalShares	100
	OwnershipUpperLimit	0.2
	TickSize	1
	LotSize	1
Iceberg	7	4	3	5	6	SELL	0	---	0
NewOrderRs	Accepted
	Trades	0
	Orders	3
	Order	Limit	6	7	2	3	8	SELL	0	---	0
	Order	Limit	2	3	2	5	6	SELL	0	---	0
	Order	Iceberg	7	4	3	5	6	SELL	0	---	5
	Credits	7
	Credit	1	12
	Credit	2	6
	Credit	3	9
	Credit	4	13
	Credit	5	4
	Credit	6	13
	Credit	7	14
	Ownerships	7
	Ownership	1	80
	Ownership	2	35
	Ownership	3	41
	Ownership	4	16
	Ownership	5	18
	Ownership	6	27
	Ownership	7	42
	ReferencePrice	5
	StaticPriceBandLowerLimit	0.6
	StaticPriceBandUpperLimit	0.8
	TotalShares	100
	OwnershipUpperLimit	0.2
	TickSize	1
	LotSize	1
Limit	8	3	5	5	1	SELL	0	---	0
NewOrderRs	Accepted
	Trades	0
	Orders	4
	Order	Limit	6	7	2	3	8	SELL	0	---	0
	Order	Limit	2	3	2	5	6	SELL	0	---	0
	Order	Iceberg	7	4	3	5	6	SELL	0	---	5
	Order	Limit	8	3	5	5	1	SELL	0	---	0
	Credits	7
	Credit	1	12
	Credit	2	6
	Credit	3	9
	Credit	4	13
	Credit	5	4
	Credit	6	13
	Credit	7	14
	Ownerships	7
	Ownership	1	80
	Ownership	2	35
	Ownership	3	41
	Ownership	4	16
	Ownership	5	18
	Ownership	6	27
	Ownership	7	42
	ReferencePrice	5
	StaticPriceBandLowerLimit	0.6
	StaticPriceBandUpperLimit	0.8
	TotalShares	100
	OwnershipUpperLimit	0.2
	TickSize	1
	LotSize	1
Iceberg	9	3	6	2	8	BUY 	0	---	0
NewOrderRs	Rejected
	Trades	0
	Orders	4
	Order	Limit	6	7	2	3	8	SELL	0	---	0
	Order	Limit	2	3	2	5	6	SELL	0	---	0
	Order	Iceberg	7	4	3	5	6	SELL	0	---	5
	Order	Limit	8	3	5	5	1	SELL	0	---	0
	Credits	7
	Credit	1	12
	Credit	2	6
	Credit	3	9
	Credit	4	13
	Credit	5	4
	Credit	6	13
	Credit	7	14
	Ownerships	7
	Ownership	1	80
	Ownership	2	35
	Ownership	3	41
	Ownership	4	16
	Ownership	5	18
	Ownership	6	27
	Ownership	7	42
	ReferencePrice	5
	StaticPriceBandLowerLimit	0.6
	StaticPriceBandUpperLimit	0.8
	TotalShares	100
	OwnershipUpperLimit	0.2
	TickSize	1
	LotSize	1
Limit	10	3	6	5	1	BUY 	0	FAK	0
ReplaceOrderRs	Rejected
	Trades	0
	Orders	4
	Order	Limit	6	7	2	3	8	SELL	0	---	0
	Order	Limit	2	3	2	5	6	SELL	0	---	0
	Order	Iceberg	7	4	3	5	6	SELL	0	---	5
	Order	Limit	8	3	5	5	1	SELL	0	---	0
	Credits	7
	Credit	1	12
	Credit	2	6
	Credit	3	9
	Credit	4	13
	Credit	5	4
	Credit	6	13
	Credit	7	14
	Ownerships	7
	Ownership	1	80
	Ownership	2	35
	Ownership	3	41
	Ownership	4	16
	Ownership	5	18
	Ownership	6	27
	Ownership	7	42
	ReferencePrice	5
	StaticPriceBandLowerLimit	0.6
	StaticPriceBandUpperLimit	0.8
	TotalShares	100
	OwnershipUpperLimit	0.2
	TickSize	1
	LotSize	1
Limit	11	5	1	4	6	BUY 	0	FAK	0
NewOrderRs	Rejected
	Trades	0
	Orders	4
	Order	Limit	6	7	2	3	8	SELL	0	---	0
	Order	Limit	2	3	2	5	6	SELL	0	---	0
	Order	Iceberg	7	4	3	5	6	SELL	0	---	5
	Order	Limit	8	3	5	5	1	SELL	0	---	0
	Credits	7
	Credit	1	12
	Credit	2	6
	Credit	3	9
	Credit	4	13
	Credit	5	4
	Credit	6	13
	Credit	7	14
	Ownerships	7
	Ownership	1	80
	Ownership	2	35
	Ownership	3	41
	Ownership	4	16
	Ownership	5	18
	Ownership	6	27
	Ownership	7	42
	ReferencePrice	5
	StaticPriceBandLowerLimit	0.6
	StaticPriceBandUpperLimit	0.8
	TotalShares	100
	OwnershipUpperLimit	0.2
	TickSize	1
	LotSize	1
Iceberg	12	3	4	3	3	BUY 	1	---	0
NewOrderRs	Accepted
	Trades	1
	Trade	3	3	12	6
	Orders	4
	Order	Limit	6	7	2	3	5	SELL	0	---	0
	Order	Limit	2	3	2	5	6	SELL	0	---	0
	Order	Iceberg	7	4	3	5	6	SELL	0	---	5
	Order	Limit	8	3	5	5	1	SELL	0	---	0
	Credits	7
	Credit	1	12
	Credit	2	6
	Credit	3	0
	Credit	4	13
	Credit	5	4
	Credit	6	13
	Credit	7	23
	Ownerships	7
	Ownership	1	80
	Ownership	2	32
	Ownership	3	41
	Ownership	4	19
	Ownership	5	18
	Ownership	6	27
	Ownership	7	42
	ReferencePrice	5
	StaticPriceBandLowerLimit	0.6
	StaticPriceBandUpperLimit	0.8
	TotalShares	100
	OwnershipUpperLimit	0.2
	TickSize	1
	LotSize	1
Limit	13	4	1	6	2	SELL	0	FAK	0
NewOrderRs	Eliminated
	Trades	0
	Orders	4
	Order	Limit	6	7	2	3	5	SELL	0	---	0
	Order	Limit	2	3	2	5	6	SELL	0	---	0
	Order	Iceberg	7	4	3	5	6	SELL	0	---	5
	Order	Limit	8	3	5	5	1	SELL	0	---	0
	Credits	7
	Credit	1	12
	Credit	2	6
	Credit	3	0
	Credit	4	13
	Credit	5	4
	Credit	6	13
	Credit	7	23
	Ownerships	7
	Ownership	1	80
	Ownership	2	32
	Ownership	3	41
	Ownership	4	19
	Ownership	5	18
	Ownership	6	27
	Ownership	7	42
	ReferencePrice	5
	StaticPriceBandLowerLimit	0.6
	StaticPriceBandUpperLimit	0.8
	TotalShares	100
	OwnershipUpperLimit	0.2
	TickSize	1
	LotSize	1
Iceberg	14	7	5	6	4	BUY 	0	---	0
NewOrderRs	Rejected
	Trades	0
	Orders	4
	Order	Limit	6	7	2	3	5	SELL	0	---	0
	Order	Limit	2	3	2	5	6	SELL	0	---	0
	Order	Iceberg	7	4	3	5	6	SELL	0	---	5
	Order	Limit	8	3	5	5	1	SELL	0	---	0
	Credits	7
	Credit	1	12
	Credit	2	6
	Credit	3	0
	Credit	4	13
	Credit	5	4
	Credit	6	13
	Credit	7	23
	Ownerships	7
	Ownership	1	80
	Ownership	2	32
	Ownership	3	41
	Ownership	4	19
	Ownership	5	18
	Ownership	6	27
	Ownership	7	42
	ReferencePrice	5
	StaticPriceBandLowerLimit	0.6
	StaticPriceBandUpperLimit	0.8
	TotalShares	100
	OwnershipUpperLimit	0.2
	TickSize	1
	LotSize	1
CancelOrderRs	Rejected
	Orders	4
	Order	Limit	6	7	2	3	5	SELL	0	---	0
	Order	Limit	2	3	2	5	6	SELL	0	---	0
	Order	Iceberg	7	4	3	5	6	SELL	0	---	5
	Order	Limit	8	3	5	5	1	SELL	0	---	0
	Credits	7
	Credit	1	12
	Credit	2	6
	Credit	3	0
	Credit	4	13
	Credit	5	4
	Credit	6	13
	Credit	7	23
	Ownerships	7
	Ownership	1	80
	Ownership	2	32
	Ownership	3	41
	Ownership	4	19
	Ownership	5	18
	Ownership	6	27
	Ownership	7	42
	ReferencePrice	5
	StaticPriceBandLowerLimit	0.6
	StaticPriceBandUpperLimit	0.8
	TotalShares	100
