reported_result/report-0/ART_AutoISP_noPartition/output/output6.txt

Limit	1	7	2	6	4	SELL	3	---	0
NewOrderRs	Eliminated
	Trades	0
	Orders	0
	Credits	7
	Credit	1	10
	Credit	2	2
	Credit	3	8
	Credit	4	8
	Credit	5	13
	Credit	6	16
	Credit	7	14
	Ownerships	7
	Ownership	1	10
	Ownership	2	54
	Ownership	3	5
	Ownership	4	15
	Ownership	5	11
	Ownership	6	35
	Ownership	7	76
	ReferencePrice	5
	StaticPriceBandLowerLimit	0.6
	StaticPriceBandUpperLimit	0.8
	TotalShares	100
	OwnershipUpperLimit	0.2
	TickSize	1
	LotSize	1
Iceberg	2	1	2	4	5	SELL	0	---	0
NewOrderRs	Accepted
	Trades	0
	Orders	1
	Order	Iceberg	2	1	2	4	5	SELL	0	---	2
	Credits	7
	Credit	1	10
	Credit	2	2
	Credit	3	8
	Credit	4	8
	Credit	5	13
	Credit	6	16
	Credit	7	14
	Ownerships	7
	Ownership	1	10
	Ownership	2	54
	Ownership	3	5
	Ownership	4	15
	Ownership	5	11
	Ownership	6	35
	Ownership	7	76
	ReferencePrice	5
	StaticPriceBandLowerLimit	0.6
	StaticPriceBandUpperLimit	0.8
	TotalShares	100
	OwnershipUpperLimit	0.2
	TickSize	1
	LotSize	1
Limit	3	5	6	4	4	SELL	0	---	0
NewOrderRs	Accepted
	Trades	0
	Orders	2
	Order	Iceberg	2	1	2	4	5	SELL	0	---	2
	Order	Limit	3	5	6	4	4	SELL	0	---	0
	Credits	7
	Credit	1	10
	Credit	2	2
	Credit	3	8
	Credit	4	8
	Credit	5	13
	Credit	6	16
	Credit	7	14
	Ownerships	7
	Ownership	1	10
	Ownership	2	54
	Ownership	3	5
	Ownership	4	15
	Ownership	5	11
	Ownership	6	35
	Ownership	7	76
	ReferencePrice	5
	StaticPriceBandLowerLimit	0.6
	StaticPriceBandUpperLimit	0.8
	TotalShares	100
	OwnershipUpperLimit	0.2
	TickSize	1
	LotSize	1
Limit	4	6	6	6	2	BUY 	0	FAK	0
NewOrderRs	Rejected
	Trades	0
	Orders	2
	Order	Iceberg	2	1	2	4	5	SELL	0	---	2
	Order	Limit	3	5	6	4	4	SELL	0	---	0
	Credits	7
	Credit	1	10
	Credit	2	2
	Credit	3	8
	Credit	4	8
	Credit	5	13
	Credit	6	16
	Credit	7	14
	Ownerships	7
	Ownership	1	10
	Ownership	2	54
	Ownership	3	5
	Ownership	4	15
	Ownership	5	11
	Ownership	6	35
	Ownership	7	76
	ReferencePrice	5
	StaticPriceBandLowerLimit	0.6
	StaticPriceBandUpperLimit	0.8
	TotalShares	100
	OwnershipUpperLimit	0.2
	TickSize	1
	LotSize	1
CancelOrderRs	Rejected
	Orders	2
	Order	Iceberg	2	1	2	4	5	SELL	0	---	2
	Order	Limit	3	5	6	4	4	SELL	0	---	0
	Credits	7
	Credit	1	10
	Credit	2	2
	Credit	3	8
	Credit	4	8
	Credit	5	13
	Credit	6	16
	Credit	7	14
	Ownerships	7
	Ownership	1	10
	Ownership	2	54
	Ownership	3	5
	Ownership	4	15
	Ownership	5	11
	Ownership	6	35
	Ownership	7	76
	ReferencePrice	5
	StaticPriceBandLowerLimit	0.6
	StaticPriceBandUpperLimit	0.8
	TotalShares	100
	OwnershipUpperLimit	0.2
	TickSize	1
	LotSize	1
Limit	6	5	5	3	5	BUY 	1	---	0
NewOrderRs	Eliminated
	Trades	0
	Orders	2
	Order	Iceberg	2	1	2	4	5	SELL	0	---	2
	Order	Limit	3	5	6	4	4	SELL	0	---	0
	Credits	7
	Credit	1	10
	Credit	2	2
	Credit	3	8
	Credit	4	8
	Credit	5	13
	Credit	6	16
	Credit	7	14
	Ownerships	7
	Ownership	1	10
	Ownership	2	54
	Ownership	3	5
	Ownership	4	15
	Ownership	5	11
	Ownership	6	35
	Ownership	7	76
	ReferencePrice	5
	StaticPriceBandLowerLimit	0.6
	StaticPriceBandUpperLimit	0.8
	TotalShares	100
	OwnershipUpperLimit	0.2
	TickSize	1
	LotSize	1
Iceberg	7	4	3	4	1	BUY 	0	---	0
NewOrderRs	Accepted
	Trades	1
	Trade	4	1	7	2
	Orders	2
	Order	Iceberg	2	1	2	4	4	SELL	0	---	1
	Order	Limit	3	5	6	4	4	SELL	0	---	0
	Credits	7
	Credit	1	14
	Credit	2	2
	Credit	3	8
	Credit	4	4
	Credit	5	13
	Credit	6	16
	Credit	7	14
	Ownerships	7
	Ownership	1	10
	Ownership	2	53
	Ownership	3	6
	Ownership	4	15
	Ownership	5	11
	Ownership	6	35
	Ownership	7	76
	ReferencePrice	5
	StaticPriceBandLowerLimit	0.6
	StaticPriceBandUpperLimit	0.8
	TotalShares	100
	OwnershipUpperLimit	0.2
	TickSize	1
	LotSize	1
Iceberg	8	5	6	6	1	BUY 	1	---	0
NewOrderRs	Rejected
	Trades	0
	Orders	2
	Order	Iceberg	2	1	2	4	4	SELL	0	---	1
	Order	Limit	3	5	6	4	4	SELL	0	---	0
	Credits	7
	Credit	1	14
	Credit	2	2
	Credit	3	8
	Credit	4	4
	Credit	5	13
	Credit	6	16
	Credit	7	14
	Ownerships	7
	Ownership	1	10
	Ownership	2	53
	Ownership	3	6
	Ownership	4	15
	Ownership	5	11
	Ownership	6	35
	Ownership	7	76
	ReferencePrice	5
	StaticPriceBandLowerLimit	0.6
	StaticPriceBandUpperLimit	0.8
	TotalShares	100
	OwnershipUpperLimit	0.2
	TickSize	1
	LotSize	1
Limit	9	5	6	9	8	SELL	0	FAK	0
NewOrderRs	Eliminated
	Trades	0
	Orders	2
	Order	Iceberg	2	1	2	4	4	SELL	0	---	1
	Order	Limit	3	5	6	4	4	SELL	0	---	0
	Credits	7
	Credit	1	14
	Credit	2	2
	Credit	3	8
	Credit	4	4
	Credit	5	13
	Credit	6	16
	Credit	7	14
	Ownerships	7
	Ownership	1	10
	Ownership	2	53
	Ownership	3	6
	Ownership	4	15
	Ownership	5	11
	Ownership	6	35
	Ownership	7	76
	ReferencePrice	5
	StaticPriceBandLowerLimit	0.6
	StaticPriceBandUpperLimit	0.8
	TotalShares	100
	OwnershipUpperLimit	0.2
	TickSize	1
	LotSize	1
Iceberg	10	5	6	7	4	SELL	4	---	0
ReplaceOrderRs	Rejected
	Trades	0
	Orders	2
	Order	Iceberg	2	1	2	4	4	SELL	0	---	1
	Order	Limit	3	5	6	4	4	SELL	0	---	0
	Credits	7
	Credit	1	14
	Credit	2	2
	Credit	3	8
	Credit	4	4
	Credit	5	13
	Credit	6	16
	Credit	7	14
	Ownerships	7
	Ownership	1	10
	Ownership	2	53
	Ownership	3	6
	Ownership	4	15
	Ownership	5	11
	Ownership	6	35
	Ownership	7	76
	ReferencePrice	5
	StaticPriceBandLowerLimit	0.6
	StaticPriceBandUpperLimit	0.8
	TotalShares	100
	OwnershipUpperLimit	0.2
	TickSize	1
	LotSize	1
Limit	11	4	3	8	3	SELL	0	---	0
NewOrderRs	Accepted
	Trades	0
	Orders	3
	Order	Iceberg	2	1	2	4	4	SELL	0	---	1
	Order	Limit	3	5	6	4	4	SELL	0	---	0
	Order	Limit	11	4	3	8	3	SELL	0	---	0
	Credits	7
	Credit	1	14
	Credit	2	2
	Credit	3	8
	Credit	4	4
	Credit	5	13
	Credit	6	16
	Credit	7	14
	Ownerships	7
	Ownership	1	10
	Ownership	2	53
	Ownership	3	6
	Ownership	4	15
	Ownership	5	11
	Ownership	6	35
	Ownership	7	76
	ReferencePrice	5
	StaticPriceBandLowerLimit	0.6
	StaticPriceBandUpperLimit	0.8
	TotalShares	100
	OwnershipUpperLimit	0.2
	TickSize	1
	LotSize	1
Iceberg	12	4	7	3	3	SELL	0	---	0
NewOrderRs	Accepted
	Trades	0
	Orders	4
	Order	Iceberg	12	4	7	3	3	SELL	0	---	2
	Order	Iceberg	2	1	2	4	4	SELL	0	---	1
	Order	Limit	3	5	6	4	4	SELL	0	---	0
	Order	Limit	11	4	3	8	3	SELL	0	---	0
	Credits	7
	Credit	1	14
	Credit	2	2
	Credit	3	8
	Credit	4	4
	Credit	5	13
	Credit	6	16
	Credit	7	14
	Ownerships	7
	Ownership	1	10
	Ownership	2	53
	Ownership	3	6
	Ownership	4	15
	Ownership	5	11
	Ownership	6	35
	Ownership	7	76
	ReferencePrice	5
	StaticPriceBandLowerLimit	0.6
	StaticPriceBandUpperLimit	0.8
	TotalShares	100
	OwnershipUpperLimit	0.2
	TickSize	1
	LotSize	1
Iceberg	13	1	7	5	3	BUY 	0	---	0
NewOrderRs	Rejected
	Trades	0
	Orders	4
	Order	Iceberg	12	4	7	3	3	SELL	0	---	2
	Order	Iceberg	2	1	2	4	4	SELL	0	---	1
	Order	Limit	3	5	6	4	4	SELL	0	---	0
	Order	Limit	11	4	3	8	3	SELL	0	---	0
	Credits	7
	Credit	1	14
	Credit	2	2
	Credit	3	8
	Credit	4	4
	Credit	5	13
	Credit	6	16
	Credit	7	14
	Ownerships	7
	Ownership	1	10
	Ownership	2	53
	Ownership	3	6
	Ownership	4	15
	Ownership	5	11
	Ownership	6	35
	Ownership	7	76
	ReferencePrice	5
	StaticPriceBandLowerLimit	0.6
	StaticPriceBandUpperLimit	0.8
	TotalShares	100
	OwnershipUpperLimit	0.2
	TickSize	1
	LotSize	1
Limit	14	2	5	9	1	BUY 	0	FAK	0
NewOrderRs	Rejected
	Trades	0
	Orders	4
	Order	Iceberg	12	4	7	3	3	SELL	0	---	2
	Order	Iceberg	2	1	2	4	4	SELL	0	---	1
	Order	Limit	3	5	6	4	4	SELL	0	---	0
	Order	Limit	11	4	3	8	3	SELL	0	---	0
	Credits	7
	Credit	1	14
	Credit	2	2
	Credit	3	8
	Credit	4	4
	Credit	5	13
	Credit	6	16
	Credit	7	14
	Ownerships	7
	Ownership	1	10
	Ownership	2	53
	Ownership	3	6
	Ownership	4	15
	Ownership	5	11
	Ownership	6	35
	Ownership	7	76
	ReferencePrice	5
	StaticPriceBandLowerLimit	0.6
	StaticPriceBandUpperLimit	0.8
	TotalShares	100
	OwnershipUpperLimit	0.2
	TickSize	1
	LotSize	1
CancelOrderRs	Rejected
	Orders	4
	Order	Iceberg	12	4	7	3	3	SELL	0	---	2
	Order	Iceberg	2	1	2	4	4	SELL	0	---	1
	Order	Limit	3	5	6	4	4	SELL	0	---	0
	Order	Limit	11	4	3	8	3	SELL	0	---	0
	Credits	7
	Credit	1	14
	Credit	2	2
	Credit	3	8
	Credit	4	4
	Credit	5	13
	Credit	6	16
	Credit	7	14
	Ownerships	7
	Ownership	1	10
	Ownership	2	53
	Ownership	3	6
	Ownership	4	15
	Ownership	5	11
	Ownership	6	35
	Ownership	7	76
	ReferencePrice	5
	StaticPriceBandLowerLimit	0.6
	StaticPriceBandUpperLimit	0.8
	TotalShares	100
	OwnershipUpperLimit	0.2
	TickSize	1
	LotSize	1
Iceberg	16	2	4	6	7	BUY 	4	---	0
NewOrderRs	Rejected
	Trades	0
	Orders	4
	Order	Iceberg	12	4	7	3	3	SELL	0	---	2
	Order	Iceberg	2	1	2	4	4	SELL	0	---	1
